Loading .env environment variables...
There was an error while trying to get the Signer
Loading .env environment variables...
Loading .env environment variables...
There was an error while trying to construct a  oci.auth.signers.InstancePrincipalsSecurityTokenSigner object
Traceback (most recent call last):
  File "objectstoreaccess.py", line 192, in __init__
    self.signer = oci.auth.signers.InstancePrincipalsSecurityTokenSigner()
  File "/home/ubuntu/.local/share/virtualenvs/gpasfasta-UAGKCmH3/lib/python3.8/site-packages/oci/auth/signers/instance_principals_security_token_signer.py", line 112, in __init__
    super(InstancePrincipalsSecurityTokenSigner, self).__init__(federation_client)
  File "/home/ubuntu/.local/share/virtualenvs/gpasfasta-UAGKCmH3/lib/python3.8/site-packages/oci/auth/signers/security_token_signer.py", line 51, in __init__
    self.federation_client.get_security_token(),
  File "/home/ubuntu/.local/share/virtualenvs/gpasfasta-UAGKCmH3/lib/python3.8/site-packages/oci/auth/federation_client.py", line 117, in get_security_token
    return self._refresh_security_token_inner()
  File "/home/ubuntu/.local/share/virtualenvs/gpasfasta-UAGKCmH3/lib/python3.8/site-packages/oci/auth/federation_client.py", line 133, in _refresh_security_token_inner
    self.retry_strategy.make_retrying_call(self._get_security_token_from_auth_service)
  File "/home/ubuntu/.local/share/virtualenvs/gpasfasta-UAGKCmH3/lib/python3.8/site-packages/oci/retry/retry.py", line 279, in make_retrying_call
    return func_ref(*func_args, **func_kwargs)
  File "/home/ubuntu/.local/share/virtualenvs/gpasfasta-UAGKCmH3/lib/python3.8/site-packages/oci/auth/federation_client.py", line 181, in _get_security_token_from_auth_service
    raise oci.exceptions.ServiceError(
oci.exceptions.ServiceError: {'opc-request-id': '/06294585182E65FC48256ACB6265B380/E39C8197F990594E6C6E907066ED160F', 'code': 'NotAuthenticated', 'message': 'The required information to complete authentication was not provided or was incorrect.', 'status': 401}

During handling of the above exception, another exception occurred:

Traceback (most recent call last):
  File "objectstoreaccess.py", line 901, in <module>
    n_inserted = os2fn4.insert_files_into_server()
  File "objectstoreaccess.py", line 681, in insert_files_into_server
    input_ba = BucketAccess(
  File "objectstoreaccess.py", line 195, in __init__
    capture(e)
NameError: name 'capture' is not defined
